Workbook

Sheet Assumptions
A1: 0.01
A3: PRODUCT SPECIFICATIONS | C3: Retail Price ($/bulb) | D3: Price Change (% p.a.) | E3: Power (Watts) | F3: Bulb Life (hrs) | G3: Installed Base % (2010)
B4: Standard | C4: 0.5 | D4: 0 | E4: 60 | F4: 1000 | G4: 0.82
B5: CFL | C5: 3 | D5: -0.04 | E5: 15 | F5: 8000 | G5: 0.17
B6: LED | C6: 40 | D6: -0.1 | E6: 7 | F6: 50000 | G6: 0.01
A8: PRICE ASSUMPTIONS
B9: Standard | C9: Base Price 2010 ($/bulb) | D9: Annual Change
B10: CFL | C10: =C4 -> 0.5 | D10: =D4 -> 0
B11: LED | C11: =C5 -> 3 | D11: =D5 -> -0.04
C12: =C6 -> 40 | D12: =D6 -> -0.1
A13: MARKET ASSUMPTIONS
B14: Annual usage (hrs/yr)
B15: Developed installed base 2010 (m bulbs) | C15: 1100
B16: Emerging installed base 2010 (m bulbs) | C16: 4500
B17: New build growth - Developed | C17: 6000
B18: New build growth - Emerging | C18: 0.01
B19: Incandescent phase-out start (Developed) | C19: 0.04
B20: Incandescent phase-out end (Developed) | C20: 2014
C21: 2018
A22: FINANCIAL ASSUMPTIONS
B23: Tax rate
B24: WACC (discount rate) | C24: 0.25
B25: NWC as % of revenue | C25: 0.1
B26: Corporate overhead ($m) | C26: 0.05
B27: Experience curve rate | C27: 6
B28: GE target market share | C28: 0.85
C29: 0.25
A31: SWITCHING RATES (2010 BASE)
A32: REPLACEMENT MARKET | E32: Developed | H32: Emerging
A33: Std that needs replacing:
B34: Stays with Std | E34: 0.87 | H34: 0.96
B35: Switches to CFL | E35: 0.12 | H35: 0.04
B36: Switches to LED | E36: 0.01 | H36: 0.003
A37: CFL that needs replacing:
B38: Stays with CFL | E38: 1 | H38: 1
B39: Switches to LED | E39: 0 | H39: 0
A41: NEW BUILD MARKET | E41: Developed | H41: Emerging
B42: Standard | E42: 0.74 | H42: 0.92
B43: CFL | E43: 0.23 | H43: 0.08
B44: LED | E44: 0.03 | H44: 0.0012
...

Sheet Demand - Developed
A1: DEMAND MODEL — DEVELOPED MARKETS
A3: m bulbs | C3: 2010 | D3: 2011 | E3: 2012 | F3: 2013 | G3: 2014 | H3: 2015 | I3: 2016 | J3: 2017 | K3: 2018 | L3: 2019 | M3: 2020 | N3: 2021 | O3: 2022 | P3: 2023 | Q3: 2024 | R3: 2025
A5: PRICE PROJECTIONS ($/bulb) | C5: retail price ($/bulb)
A6: Standard | C6: =Assumptions!C4 -> 0.5 | D6: =C6*(1+Assumptions!$D$4) -> 0.5 | E6: =D6*(1+Assumptions!$D$4) -> 0.5 | F6: =E6*(1+Assumptions!$D$4) -> 0.5 | G6: =F6*(1+Assumptions!$D$4) -> 0.5 | H6: =G6*(1+Assumptions!$D$4) -> 0.5 | I6: =H6*(1+Assumptions!$D$4) -> 0.5 | J6: =I6*(1+Assumptions!$D$4) -> 0.5 | K6: =J6*(1+Assumptions!$D$4) -> 0.5 | ... R6: =Q6*(1+Assumptions!$D$4) -> 0.5
A7: CFL | C7: =Assumptions!C5 -> 3 | D7: =C7*(1+Assumptions!$D$5) -> 2.88 | E7: =D7*(1+Assumptions!$D$5) -> 2.7648 | F7: =E7*(1+Assumptions!$D$5) -> 2.654208 | G7: =F7*(1+Assumptions!$D$5) -> 2.5480397 | H7: =G7*(1+Assumptions!$D$5) -> 2.4461181 | I7: =H7*(1+Assumptions!$D$5) -> 2.3482734 | J7: =I7*(1+Assumptions!$D$5) -> 2.2543424 | K7: =J7*(1+Assumptions!$D$5) -> 2.1641687 | ... R7: =Q7*(1+Assumptions!$D$5) -> 1.6262591
A8: LED | C8: =Assumptions!C6 -> 40 | D8: =C8*(1+Assumptions!$D$6) -> 36 | E8: =D8*(1+Assumptions!$D$6) -> 32.4 | F8: =E8*(1+Assumptions!$D$6) -> 29.16 | G8: =F8*(1+Assumptions!$D$6) -> 26.244 | H8: =G8*(1+Assumptions!$D$6) -> 23.6196 | I8: =H8*(1+Assumptions!$D$6) -> 21.25764 | J8: =I8*(1+Assumptions!$D$6) -> 19.131876 | K8: =J8*(1+Assumptions!$D$6) -> 17.218688 | ... R8: =Q8*(1+Assumptions!$D$6) -> 8.2356453
C10: Developed Switching
C11: =Assumptions!E34 -> 0.87 | D11: =MAX(1-D12-D13,0) -> 0.85 | E11: =MAX(1-E12-E13,0) -> 0.83 | F11: =MAX(1-F12-F13,0) -> 0.81 | G11: =MAX(1-G12-G13,0) -> 0.78 | H11: =MAX(1-H12-H13,0) -> 0.75 | I11: =MAX(1-I12-I13,0) -> 0.72 | J11: =MAX(1-J12-J13,0) -> 0.69 | K11: =MAX(1-K12-K13,0) -> 0.66 | ... R11: =MAX(1-R12-R13,0) -> 0.57
C12: =Assumptions!E35 -> 0.12 | D12: =MIN(C12+Assumptions!$E$47,0.3) -> 0.14 | E12: =MIN(D12+Assumptions!$E$47,0.3) -> 0.16 | F12: =MIN(E12+Assumptions!$E$47,0.3) -> 0.18 | G12: =MIN(F12+Assumptions!$E$47,0.3) -> 0.2 | H12: =MIN(G12+Assumptions!$E$47,0.3) -> 0.22 | I12: =MIN(H12+Assumptions!$E$47,0.3) -> 0.24 | J12: =MIN(I12+Assumptions!$E$47,0.3) -> 0.26 | K12: =MIN(J12+Assumptions!$E$47,0.3) -> 0.28 | ... R12: =MIN(Q12+Assumptions!$E$47,0.3) -> 0.3
C13: =Assumptions!E36 -> 0.01 | D13: =IF(D$3>=Assumptions!$C$20,C13+Assumptions!$E$49,C13) -> 0.01 | E13: =IF(E$3>=Assumptions!$C$20,D13+Assumptions!$E$49,D13) -> 0.01 | F13: =IF(F$3>=Assumptions!$C$20,E13+Assumptions!$E$49,E13) -> 0.01 | G13: =IF(G$3>=Assumptions!$C$20,F13+Assumptions!$E$49,F13) -> 0.02 | H13: =IF(H$3>=Assumptions!$C$20,G13+Assumptions!$E$49,G13) -> 0.03 | I13: =IF(I$3>=Assumptions!$C$20,H13+Assumptions!$E$49,H13) -> 0.04 | J13: =IF(J$3>=Assumptions!$C$20,I13+Assumptions!$E$49,I13) -> 0.05 | K13: =IF(K$3>=Assumptions!$C$20,J13+Assumptions!$E$49,J13) -> 0.06 | ... R13: =IF(R$3>=Assumptions!$C$20,Q13+Assumptions!$E$49,Q13) -> 0.13
C14: =Assumptions!E38 -> 1 | D14: =MAX(1-D15,0) -> 1 | E14: =MAX(1-E15,0) -> 1 | F14: =MAX(1-F15,0) -> 1 | G14: =MAX(1-G15,0) -> 0.97 | H14: =MAX(1-H15,0) -> 0.94 | I14: =MAX(1-I15,0) -> 0.91 | J14: =MAX(1-J15,0) -> 0.88 | K14: =MAX(1-K15,0) -> 0.85 | ... R14: =MAX(1-R15,0) -> 0.8
C15: =Assumptions!E39 -> 0 | D15: =IF(D$3>=Assumptions!$C$20,MIN(C15+Assumptions!$E$50,0.2),C15) -> 0 | E15: =IF(E$3>=Assumptions!$C$20,MIN(D15+Assumptions!$E$50,0.2),D15) -> 0 | F15: =IF(F$3>=Assumptions!$C$20,MIN(E15+Assumptions!$E$50,0.2),E15) -> 0 | G15: =IF(G$3>=Assumptions!$C$20,MIN(F15+Assumptions!$E$50,0.2),F15) -> 0.03 | H15: =IF(H$3>=Assumptions!$C$20,MIN(G15+Assumptions!$E$50,0.2),G15) -> 0.06 | I15: =IF(I$3>=Assumptions!$C$20,MIN(H15+Assumptions!$E$50,0.2),H15) -> 0.09 | J15: =IF(J$3>=Assumptions!$C$20,MIN(I15+Assumptions!$E$50,0.2),I15) -> 0.12 | K15: =IF(K$3>=Assumptions!$C$20,MIN(J15+Assumptions!$E$50,0.2),J15) -> 0.15 | ... R15: =IF(R$3>=Assumptions!$C$20,MIN(Q15+Assumptions!$E$50,0.2),Q15) -> 0.2
C17: Developed New Build
C18: =Assumptions!E42 -> 0.74 | D18: =MAX(1-D19-D20,0) -> 0.68 | E18: =MAX(1-E19-E20,0) -> 0.62 | F18: =MAX(1-F19-F20,0) -> 0.56 | G18: =MAX(1-G19-G20,0) -> 0.5 | H18: =MAX(1-H19-H20,0) -> 0.44 | I18: =MAX(1-I19-I20,0) -> 0.38 | J18: =MAX(1-J19-J20,0) -> 0.32 | K18: =MAX(1-K19-K20,0) -> 0.26 | ... R18: =MAX(1-R19-R20,0) -> 0.02
C19: =Assumptions!E43 -> 0.23 | D19: =MIN(C19+0.03,0.5) -> 0.26 | E19: =MIN(D19+0.03,0.5) -> 0.29 | F19: =MIN(E19+0.03,0.5) -> 0.32 | G19: =MIN(F19+0.03,0.5) -> 0.35 | H19: =MIN(G19+0.03,0.5) -> 0.38 | I19: =MIN(H19+0.03,0.5) -> 0.41 | J19: =MIN(I19+0.03,0.5) -> 0.44 | K19: =MIN(J19+0.03,0.5) -> 0.47 | ... R19: =MIN(Q19+0.03,0.5) -> 0.5
C20: =Assumptions!E44 -> 0.03 | D20: =MIN(C20+0.03,0.5) -> 0.06 | E20: =MIN(D20+0.03,0.5) -> 0.09 | F20: =MIN(E20+0.03,0.5) -> 0.12 | G20: =MIN(F20+0.03,0.5) -> 0.15 | H20: =MIN(G20+0.03,0.5) -> 0.18 | I20: =MIN(H20+0.03,0.5) -> 0.21 | J20: =MIN(I20+0.03,0.5) -> 0.24 | K20: =MIN(J20+0.03,0.5) -> 0.27 | ... R20: =MIN(Q20+0.03,0.5) -> 0.48
C23: Developed base standard
C24: =Assumptions!C16*Assumptions!G4 -> 3690 | D24: =C30 -> 3195.63 | E24: =D30 -> 2699.2571 | F24: =E30 -> 2222.9568 | G24: =F30 -> 1784.3224 | H24: =G30 -> 1375.93 | I24: =H30 -> 1018.3592 | J24: =I30 -> 722.85658 | K24: =J30 -> 491.80123 | ... R24: =Q30 -> 19.387787
C25: =C24*(Assumptions!$C$15/Assumptions!$F$4) -> 4059 | D25: =D24*(Assumptions!$C$15/Assumptions!$F$4) -> 3515.193 | E25: =E24*(Assumptions!$C$15/Assumptions!$F$4) -> 2969.1828 | F25: =F24*(Assumptions!$C$15/Assumptions!$F$4) -> 2445.2524 | G25: =G24*(Assumptions!$C$15/Assumptions!$F$4) -> 1962.7546 | H25: =H24*(Assumptions!$C$15/Assumptions!$F$4) -> 1513.523 | I25: =I24*(Assumptions!$C$15/Assumptions!$F$4) -> 1120.1951 | J25: =J24*(Assumptions!$C$15/Assumptions!$F$4) -> 795.14223 | ... R25: =R24*(Assumptions!$C$15/Assumptions!$F$4) -> 21.326565
C26: =C25*C11 -> 3531.33 | D26: =D25*D11 -> 2987.9141 | E26: =E25*E11 -> 2464.4217 | F26: =F25*F11 -> 1980.6545 | G26: =G25*G11 -> 1530.9486 | H26: =H25*H11 -> 1135.1422 | I26: =I25*I11 -> 806.5405 | J26: =J25*J11 -> 548.64814 | ... R26: =R25*R11 -> 12.156142
C27: =C25*C12 -> 487.08 | D27: =D25*D12 -> 492.12702 | E27: =E25*E12 -> 475.06924 | F27: =F25*F12 -> 440.14544 | G27: =G25*G12 -> 392.55093 | H27: =H25*H12 -> 332.97505 | I27: =I25*I12 -> 268.84683 | J27: =J25*J12 -> 206.73698 | ... R27: =R25*R12 -> 6.3979696
C28: =C25*C13 -> 40.59 | D28: =D25*D13 -> 35.15193 | E28: =E25*E13 -> 29.691828 | F28: =F25*F13 -> 24.452524 | G28: =G25*G13 -> 39.255093 | H28: =H25*H13 -> 45.405689 | I28: =I25*I13 -> 44.807806 | J28: =J25*J13 -> 39.757112 | ... R28: =R25*R13 -> 2.7724535
C29: =Assumptions!$C$16*Assumptions!$C$18*C18 -> 33.3 | D29: =Assumptions!$C$16*Assumptions!$C$18*(1+Assumptions!$C$18)^(D$3-2010)*D18 -> 30.906 | E29: =Assumptions!$C$16*Assumptions!$C$18*(1+Assumptions!$C$18)^(E$3-2010)*E18 -> 28.46079 | F29: =Assumptions!$C$16*Assumptions!$C$18*(1+Assumptions!$C$18)^(F$3-2010)*F18 -> 25.963585 | G29: =Assumptions!$C$16*Assumptions!$C$18*(1+Assumptions!$C$18)^(G$3-2010)*G18 -> 23.41359 | H29: =Assumptions!$C$16*Assumptions!$C$18*(1+Assumptions!$C$18)^(H$3-2010)*H18 -> 20.809999 | I29: =Assumptions!$C$16*Assumptions!$C$18*(1+Assumptions!$C$18)^(I$3-2010)*I18 -> 18.151995 | J29: =Assumptions!$C$16*Assumptions!$C$18*(1+Assumptions!$C$18)^(J$3-2010)*J18 -> 15.438749 | K29: =Assumptions!$C$16*Assumptions!$C$18*(1+Assumptions!$C$18)^(K$3-2010)*K18 -> 12.669423 | ... R29: =Assumptions!$C$16*Assumptions!$C$18*(1+Assumptions!$C$18)^(R$3-2010)*R18 -> 1.0448721
C30: =C24-C25+C26+C29 -> 3195.63 | D30: =D24-D25+D26+D29 -> 2699.2571 | E30: =E24-E25+E26+E29 -> 2222.9568 | F30: =F24-F25+F26+F29 -> 1784.3224 | G30: =G24-G25+G26+G29 -> 1375.93 | H30: =H24-H25+H26+H29 -> 1018.3592 | I30: =I24-I25+I26+I29 -> 722.85658 | J30: =J24-J25+J26+J29 -> 491.80123 | ... R30: =R24-R25+R26+R29 -> 11.262236
C32: Developed Base CTL
C33: =Assumptions!C16*Assumptions!G5 -> 765 | D33: =C39 -> 1262.43 | E33: =D39 -> 1766.374 | F33: =E39 -> 2254.7556 | G33: =F39 -> 2709.7373 | H33: =G39 -> 3107.5001 | I33: =H39 -> 3432.8106 | J33: =I39 -> 3678.7614 | K33: =J39 -> 3846.0271 | ... R33: =Q39 -> 3724.3022
C34: =C33*(Assumptions!$C$15/Assumptions!$F$5) -> 105.1875 | D34: =D33*(Assumptions!$C$15/Assumptions!$F$5) -> 173.58413 | E34: =E33*(Assumptions!$C$15/Assumptions!$F$5) -> 242.87643 | F34: =F33*(Assumptions!$C$15/Assumptions!$F$5) -> 310.02889 | G34: =G33*(Assumptions!$C$15/Assumptions!$F$5) -> 372.58888 | H34: =H33*(Assumptions!$C$15/Assumptions!$F$5) -> 427.28127 | I34: =I33*(Assumptions!$C$15/Assumptions!$F$5) -> 472.01145 | J34: =J33*(Assumptions!$C$15/Assumptions!$F$5) -> 505.82969 | ... R34: =R33*(Assumptions!$C$15/Assumptions!$F$5) -> 512.09155
C35: =C34*C14 -> 105.1875 | D35: =D34*D14 -> 173.58413 | E35: =E34*E14 -> 242.87643 | F35: =F34*F14 -> 310.02889 | G35: =G34*G14 -> 361.41122 | H35: =H34*H14 -> 401.64439 | I35: =I34*I14 -> 429.53042 | J35: =J34*J14 -> 445.13013 | ... R35: =R34*R14 -> 409.67324
C36: =C34*C15 -> 0 | D36: =D34*D15 -> 0 | E36: =E34*E15 -> 0 | F36: =F34*F15 -> 0 | G36: =G34*G15 -> 11.177667 | H36: =H34*H15 -> 25.636876 | I36: =I34*I15 -> 42.481031 | J36: =J34*J15 -> 60.699563 | ... R36: =R34*R15 -> 102.41831
C37: =C27 -> 487.08 | D37: =D27 -> 492.12702 | E37: =E27 -> 475.06924 | F37: =F27 -> 440.14544 | G37: =G27 -> 392.55093 | H37: =H27 -> 332.97505 | I37: =I27 -> 268.84683 | J37: =J27 -> 206.73698 | ... R37: =R27 -> 6.3979696
C38: =Assumptions!$C$16*Assumptions!$C$18*C19 -> 10.35 | D38: =Assumptions!$C$16*Assumptions!$C$18*(1+Assumptions!$C$18)^(D$3-2010)*D19 -> 11.817 | E38: =Assumptions!$C$16*Assumptions!$C$18*(1+Assumptions!$C$18)^(E$3-2010)*E19 -> 13.312305 | F38: =Assumptions!$C$16*Assumptions!$C$18*(1+Assumptions!$C$18)^(F$3-2010)*F19 -> 14.836334 | G38: =Assumptions!$C$16*Assumptions!$C$18*(1+Assumptions!$C$18)^(G$3-2010)*G19 -> 16.389513 | H38: =Assumptions!$C$16*Assumptions!$C$18*(1+Assumptions!$C$18)^(H$3-2010)*H19 -> 17.972272 | I38: =Assumptions!$C$16*Assumptions!$C$18*(1+Assumptions!$C$18)^(I$3-2010)*I19 -> 19.585047 | J38: =Assumptions!$C$16*Assumptions!$C$18*(1+Assumptions!$C$18)^(J$3-2010)*J19 -> 21.22828 | K38: =Assumptions!$C$16*Assumptions!$C$18*(1+Assumptions!$C$18)^(K$3-2010)*K19 -> 22.902419 | ... R38: =Assumptions!$C$16*Assumptions!$C$18*(1+Assumptions!$C$18)^(R$3-2010)*R19 -> 26.121801
C39: =C33-C34+C35+C37+C38 -> 1262.43 | D39: =D33-D34+D35+D37+D38 -> 1766.374 | E39: =E33-E34+E35+E37+E38 -> 2254.7556 | F39: =F33-F34+F35+F37+F38 -> 2709.7373 | G39: =G33-G34+G35+G37+G38 -> 3107.5001 | H39: =H33-H34+H35+H37+H38 -> 3432.8106 | I39: =I33-I34+I35+I37+I38 -> 3678.7614 | J39: =J33-J34+J35+J37+J38 -> 3846.0271 | ... R39: =R33-R34+R35+R37+R38 -> 3654.4037
C42: =Assumptions!C16*Assumptions!G6 -> 45 | D42: =C48 -> 86.94 | E42: =D48 -> 124.81893 | F42: =E48 -> 158.64216 | G42: =F48 -> 188.65831 | H42: =G48 -> 246.11515 | I42: =H48 -> 325.67089 | J42: =I48 -> 422.9911 | K42: =J48 -> 535.02683 | ... R42: =Q48 -> 1480.6703
C43: =C42*(Assumptions!$C$15/Assumptions!$F$6) -> 0.99 | D43: =D42*(Assumptions!$C$15/Assumptions!$F$6) -> 1.91268 | E43: =E42*(Assumptions!$C$15/Assumptions!$F$6) -> 2.7460165 | F43: =F42*(Assumptions!$C$15/Assumptions!$F$6) -> 3.4901276 | G43: =G42*(Assumptions!$C$15/Assumptions!$F$6) -> 4.1504829 | H43: =H42*(Assumptions!$C$15/Assumptions!$F$6) -> 5.4145333 | I43: =I42*(Assumptions!$C$15/Assumptions!$F$6) -> 7.1647597 | J43: =J42*(Assumptions!$C$15/Assumptions!$F$6) -> 9.3058041 | ... R43: =R42*(Assumptions!$C$15/Assumptions!$F$6) -> 32.574747
C44: =C43 -> 0.99 | D44: =D43 -> 1.91268 | E44: =E43 -> 2.7460165 | F44: =F43 -> 3.4901276 | G44: =G43 -> 4.1504829 | H44: =H43 -> 5.4145333 | I44: =I43 -> 7.1647597 | J44: =J43 -> 9.3058041 | ... R44: =R43 -> 32.574747
C45: =C28 -> 40.59 | D45: =D28 -> 35.15193 | E45: =E28 -> 29.691828 | F45: =F28 -> 24.452524 | G45: =G28 -> 39.255093 | H45: =H28 -> 45.405689 | I45: =I28 -> 44.807806 | J45: =J28 -> 39.757112 | ... R45: =R28 -> 2.7724535
C46: =C36 -> 0 | D46: =D36 -> 0 | E46: =E36 -> 0 | F46: =F36 -> 0 | G46: =G36 -> 11.177667 | H46: =H36 -> 25.636876 | I46: =I36 -> 42.481031 | J46: =J36 -> 60.699563 | ... R46: =R36 -> 102.41831
C47: =Assumptions!$C$16*Assumptions!$C$18*C20 -> 1.35 | D47: =Assumptions!$C$16*Assumptions!$C$18*(1+Assumptions!$C$18)^(D$3-2010)*D20 -> 2.727 | E47: =Assumptions!$C$16*Assumptions!$C$18*(1+Assumptions!$C$18)^(E$3-2010)*E20 -> 4.131405 | F47: =Assumptions!$C$16*Assumptions!$C$18*(1+Assumptions!$C$18)^(F$3-2010)*F20 -> 5.5636254 | G47: =Assumptions!$C$16*Assumptions!$C$18*(1+Assumptions!$C$18)^(G$3-2010)*G20 -> 7.0240771 | H47: =Assumptions!$C$16*Assumptions!$C$18*(1+Assumptions!$C$18)^(H$3-2010)*H20 -> 8.5131814 | I47: =Assumptions!$C$16*Assumptions!$C$18*(1+Assumptions!$C$18)^(I$3-2010)*I20 -> 10.031365 | J47: =Assumptions!$C$16*Assumptions!$C$18*(1+Assumptions!$C$18)^(J$3-2010)*J20 -> 11.579062 | K47: =Assumptions!$C$16*Assumptions!$C$18*(1+Assumptions!$C$18)^(K$3-2010)*K20 -> 13.156709 | ... R47: =Assumptions!$C$16*Assumptions!$C$18*(1+Assumptions!$C$18)^(R$3-2010)*R20 -> 25.076929
C48: =C42-C43+C44+C45+C46+C47 -> 86.94 | D48: =D42-D43+D44+D45+D46+D47 -> 124.81893 | E48: =E42-E43+E44+E45+E46+E47 -> 158.64216 | F48: =F42-F43+F44+F45+F46+F47 -> 188.65831 | G48: =G42-G43+G44+G45+G46+G47 -> 246.11515 | H48: =H42-H43+H44+H45+H46+H47 -> 325.67089 | I48: =I42-I43+I44+I45+I46+I47 -> 422.9911 | J48: =J42-J43+J44+J45+J46+J47 -> 535.02683 | ... R48: =R42-R43+R44+R45+R46+R47 -> 1610.938
A50: TOTAL DEMAND — DEVELOPED MARKETS (m bulbs)
...

Sheet Demand - Emerging
A1: DEMAND MODEL — EMERGING MARKETS
A3: m bulbs | C3: 2010 | D3: 2011 | E3: 2012 | F3: 2013 | G3: 2014 | H3: 2015 | I3: 2016 | J3: 2017 | K3: 2018 | L3: 2019 | M3: 2020 | N3: 2021 | O3: 2022 | P3: 2023 | Q3: 2024 | R3: 2025
A5: PRICE PROJECTIONS ($/bulb)
A6: Standard | C6: ='Demand - Developed'!C6 -> 0.5 | D6: ='Demand - Developed'!D6 -> 0.5 | E6: ='Demand - Developed'!E6 -> 0.5 | F6: ='Demand - Developed'!F6 -> 0.5 | G6: ='Demand - Developed'!G6 -> 0.5 | H6: ='Demand - Developed'!H6 -> 0.5 | I6: ='Demand - Developed'!I6 -> 0.5 | J6: ='Demand - Developed'!J6 -> 0.5 | ... R6: ='Demand - Developed'!R6 -> 0.5
A7: CFL | C7: ='Demand - Developed'!C7 -> 3 | D7: ='Demand - Developed'!D7 -> 2.88 | E7: ='Demand - Developed'!E7 -> 2.7648 | F7: ='Demand - Developed'!F7 -> 2.654208 | G7: ='Demand - Developed'!G7 -> 2.5480397 | H7: ='Demand - Developed'!H7 -> 2.4461181 | I7: ='Demand - Developed'!I7 -> 2.3482734 | J7: ='Demand - Developed'!J7 -> 2.2543424 | ... R7: ='Demand - Developed'!R7 -> 1.6262591
A8: LED | C8: ='Demand - Developed'!C8 -> 40 | D8: ='Demand - Developed'!D8 -> 36 | E8: ='Demand - Developed'!E8 -> 32.4 | F8: ='Demand - Developed'!F8 -> 29.16 | G8: ='Demand - Developed'!G8 -> 26.244 | H8: ='Demand - Developed'!H8 -> 23.6196 | I8: ='Demand - Developed'!I8 -> 21.25764 | J8: ='Demand - Developed'!J8 -> 19.131876 | ... R8: ='Demand - Developed'!R8 -> 8.2356453
A10: SWITCHING RATES (Replacement Market)
A11: Std→Std | C11: =Assumptions!H34 -> 0.96 | D11: =MAX(1-D12-D13,0) -> 0.947 | E11: =MAX(1-E12-E13,0) -> 0.937 | F11: =MAX(1-F12-F13,0) -> 0.927 | G11: =MAX(1-G12-G13,0) -> 0.912 | H11: =MAX(1-H12-H13,0) -> 0.897 | I11: =MAX(1-I12-I13,0) -> 0.882 | J11: =MAX(1-J12-J13,0) -> 0.867 | K11: =MAX(1-K12-K13,0) -> 0.852 | ... R11: =MAX(1-R12-R13,0) -> 0.747
A12: Std→CFL | C12: =Assumptions!H35 -> 0.04 | D12: =MIN(C12+Assumptions!$H$48,0.25) -> 0.05 | E12: =MIN(D12+Assumptions!$H$48,0.25) -> 0.06 | F12: =MIN(E12+Assumptions!$H$48,0.25) -> 0.07 | G12: =MIN(F12+Assumptions!$H$48,0.25) -> 0.08 | H12: =MIN(G12+Assumptions!$H$48,0.25) -> 0.09 | I12: =MIN(H12+Assumptions!$H$48,0.25) -> 0.1 | J12: =MIN(I12+Assumptions!$H$48,0.25) -> 0.11 | K12: =MIN(J12+Assumptions!$H$48,0.25) -> 0.12 | ... R12: =MIN(Q12+Assumptions!$H$48,0.25) -> 0.19
A13: Std→LED | C13: =Assumptions!H36 -> 0.003 | D13: =IF(D$3>=Assumptions!$C$20,C13+Assumptions!$H$49,C13) -> 0.003 | E13: =IF(E$3>=Assumptions!$C$20,D13+Assumptions!$H$49,D13) -> 0.003 | F13: =IF(F$3>=Assumptions!$C$20,E13+Assumptions!$H$49,E13) -> 0.003 | G13: =IF(G$3>=Assumptions!$C$20,F13+Assumptions!$H$49,F13) -> 0.008 | H13: =IF(H$3>=Assumptions!$C$20,G13+Assumptions!$H$49,G13) -> 0.013 | I13: =IF(I$3>=Assumptions!$C$20,H13+Assumptions!$H$49,H13) -> 0.018 | J13: =IF(J$3>=Assumptions!$C$20,I13+Assumptions!$H$49,I13) -> 0.023 | K13: =IF(K$3>=Assumptions!$C$20,J13+Assumptions!$H$49,J13) -> 0.028 | ... R13: =IF(R$3>=Assumptions!$C$20,Q13+Assumptions!$H$49,Q13) -> 0.063
A14: CFL→CFL | C14: =Assumptions!H38 -> 1 | D14: =MAX(1-D15,0) -> 1 | E14: =MAX(1-E15,0) -> 1 | F14: =MAX(1-F15,0) -> 1 | G14: =MAX(1-G15,0) -> 0.985 | H14: =MAX(1-H15,0) -> 0.97 | I14: =MAX(1-I15,0) -> 0.955 | J14: =MAX(1-J15,0) -> 0.94 | K14: =MAX(1-K15,0) -> 0.925 | ... R14: =MAX(1-R15,0) -> 0.85
A15: CFL→LED | C15: =Assumptions!H39 -> 0 | D15: =IF(D$3>=Assumptions!$C$20,MIN(C15+Assumptions!$H$50,0.15),C15) -> 0 | E15: =IF(E$3>=Assumptions!$C$20,MIN(D15+Assumptions!$H$50,0.15),D15) -> 0 | F15: =IF(F$3>=Assumptions!$C$20,MIN(E15+Assumptions!$H$50,0.15),E15) -> 0 | G15: =IF(G$3>=Assumptions!$C$20,MIN(F15+Assumptions!$H$50,0.15),F15) -> 0.015 | H15: =IF(H$3>=Assumptions!$C$20,MIN(G15+Assumptions!$H$50,0.15),G15) -> 0.03 | I15: =IF(I$3>=Assumptions!$C$20,MIN(H15+Assumptions!$H$50,0.15),H15) -> 0.045 | J15: =IF(J$3>=Assumptions!$C$20,MIN(I15+Assumptions!$H$50,0.15),I15) -> 0.06 | K15: =IF(K$3>=Assumptions!$C$20,MIN(J15+Assumptions!$H$50,0.15),J15) -> 0.075 | ... R15: =IF(R$3>=Assumptions!$C$20,MIN(Q15+Assumptions!$H$50,0.15),Q15) -> 0.15
A17: SWITCHING RATES (New Build Market)
A18: Std (new build) | C18: =Assumptions!H42 -> 0.92 | D18: =MAX(1-D19-D20,0) -> 0.8788 | E18: =MAX(1-E19-E20,0) -> 0.8388 | F18: =MAX(1-F19-F20,0) -> 0.7988 | G18: =MAX(1-G19-G20,0) -> 0.7588 | H18: =MAX(1-H19-H20,0) -> 0.7188 | I18: =MAX(1-I19-I20,0) -> 0.6788 | J18: =MAX(1-J19-J20,0) -> 0.6388 | K18: =MAX(1-K19-K20,0) -> 0.5988 | ... R18: =MAX(1-R19-R20,0) -> 0.3188
A19: CFL (new build) | C19: =Assumptions!H43 -> 0.08 | D19: =MIN(C19+0.02,0.4) -> 0.1 | E19: =MIN(D19+0.02,0.4) -> 0.12 | F19: =MIN(E19+0.02,0.4) -> 0.14 | G19: =MIN(F19+0.02,0.4) -> 0.16 | H19: =MIN(G19+0.02,0.4) -> 0.18 | I19: =MIN(H19+0.02,0.4) -> 0.2 | J19: =MIN(I19+0.02,0.4) -> 0.22 | K19: =MIN(J19+0.02,0.4) -> 0.24 | ... R19: =MIN(Q19+0.02,0.4) -> 0.38
A20: LED (new build) | C20: =Assumptions!H44 -> 0.0012 | D20: =MIN(C20+0.02,0.4) -> 0.0212 | E20: =MIN(D20+0.02,0.4) -> 0.0412 | F20: =MIN(E20+0.02,0.4) -> 0.0612 | G20: =MIN(F20+0.02,0.4) -> 0.0812 | H20: =MIN(G20+0.02,0.4) -> 0.1012 | I20: =MIN(H20+0.02,0.4) -> 0.1212 | J20: =MIN(I20+0.02,0.4) -> 0.1412 | K20: =MIN(J20+0.02,0.4) -> 0.1612 | ... R20: =MIN(Q20+0.02,0.4) -> 0.3012
A22: INSTALLED BASE DYNAMICS (m bulbs)
A23: STANDARD
A24: Beginning installed base | C24: =Assumptions!C17*Assumptions!G4 -> 4920 | D24: =C30 -> 4924.32 | E24: =D30 -> 4856.5806 | F24: =E30 -> 4737.7586 | G24: =F30 -> 4572.9666 | H24: =G30 -> 4343.3487 | I24: =H30 -> 4061.1345 | J24: =I30 -> 3740.1349 | K24: =J30 -> 3394.7013 | ... R24: =Q30 -> 1229.7927
A25: Burnouts | C25: =C24*(Assumptions!$C$15/Assumptions!$F$4) -> 5412 | D25: =D24*(Assumptions!$C$15/Assumptions!$F$4) -> 5416.752 | E25: =E24*(Assumptions!$C$15/Assumptions!$F$4) -> 5342.2387 | F25: =F24*(Assumptions!$C$15/Assumptions!$F$4) -> 5211.5345 | G25: =G24*(Assumptions!$C$15/Assumptions!$F$4) -> 5030.2632 | H25: =H24*(Assumptions!$C$15/Assumptions!$F$4) -> 4777.6835 | I25: =I24*(Assumptions!$C$15/Assumptions!$F$4) -> 4467.2479 | J25: =J24*(Assumptions!$C$15/Assumptions!$F$4) -> 4114.1484 | ... R25: =R24*(Assumptions!$C$15/Assumptions!$F$4) -> 1352.7719
A26: → Replaced with Std | C26: =C25*C11 -> 5195.52 | D26: =D25*D11 -> 5129.6641 | E26: =E25*E11 -> 5005.6776 | F26: =F25*F11 -> 4831.0925 | G26: =G25*G11 -> 4587.6 | H26: =H25*H11 -> 4285.5821 | I26: =I25*I11 -> 3940.1127 | J26: =J25*J11 -> 3566.9666 | ... R26: =R25*R11 -> 1010.5206
A27: → Switched to CFL | C27: =C25*C12 -> 216.48 | D27: =D25*D12 -> 270.8376 | E27: =E25*E12 -> 320.53432 | F27: =F25*F12 -> 364.80742 | G27: =G25*G12 -> 402.42106 | H27: =H25*H12 -> 429.99152 | I27: =I25*I12 -> 446.72479 | J27: =J25*J12 -> 452.55632 | ... R27: =R25*R12 -> 257.02667
A28: → Switched to LED | C28: =C25*C13 -> 16.236 | D28: =D25*D13 -> 16.250256 | E28: =E25*E13 -> 16.026716 | F28: =F25*F13 -> 15.634604 | G28: =G25*G13 -> 40.242106 | H28: =H25*H13 -> 62.109886 | I28: =I25*I13 -> 80.410463 | J28: =J25*J13 -> 94.625413 | ... R28: =R25*R13 -> 85.224632
A29: New build - Standard | C29: =Assumptions!$C$17*Assumptions!$C$19*C18 -> 220.8 | D29: =Assumptions!$C$17*Assumptions!$C$19*(1+Assumptions!$C$19)^(D$3-2010)*D18 -> 219.34848 | E29: =Assumptions!$C$17*Assumptions!$C$19*(1+Assumptions!$C$19)^(E$3-2010)*E18 -> 217.73906 | F29: =Assumptions!$C$17*Assumptions!$C$19*(1+Assumptions!$C$19)^(F$3-2010)*F18 -> 215.64993 | G29: =Assumptions!$C$17*Assumptions!$C$19*(1+Assumptions!$C$19)^(G$3-2010)*G18 -> 213.04528 | H29: =Assumptions!$C$17*Assumptions!$C$19*(1+Assumptions!$C$19)^(H$3-2010)*H18 -> 209.88723 | I29: =Assumptions!$C$17*Assumptions!$C$19*(1+Assumptions!$C$19)^(I$3-2010)*I18 -> 206.13565 | J29: =Assumptions!$C$17*Assumptions!$C$19*(1+Assumptions!$C$19)^(J$3-2010)*J18 -> 201.74813 | K29: =Assumptions!$C$17*Assumptions!$C$19*(1+Assumptions!$C$19)^(K$3-2010)*K18 -> 196.6798 | ... R29: =Assumptions!$C$17*Assumptions!$C$19*(1+Assumptions!$C$19)^(R$3-2010)*R18 -> 137.79379
A30: Ending installed base | C30: =C24-C25+C26+C29 -> 4924.32 | D30: =D24-D25+D26+D29 -> 4856.5806 | E30: =E24-E25+E26+E29 -> 4737.7586 | F30: =F24-F25+F26+F29 -> 4572.9666 | G30: =G24-G25+G26+G29 -> 4343.3487 | H30: =H24-H25+H26+H29 -> 4061.1345 | I30: =I24-I25+I26+I29 -> 3740.1349 | J30: =J24-J25+J26+J29 -> 3394.7013 | ... R30: =R24-R25+R26+R29 -> 1025.3352
A32: CFL
A33: Beginning installed base | C33: =Assumptions!C17*Assumptions!G5 -> 1020 | D33: =C39 -> 1255.68 | E33: =D39 -> 1551.4776 | F33: =E39 -> 1903.162 | G33: =F39 -> 2305.7648 | H33: =G39 -> 2748.3528 | I33: =H39 -> 3219.5668 | J33: =I39 -> 3707.1058 | K33: =J39 -> 4198.5597 | ... R33: =Q39 -> 6988.7976
A34: Burnouts | C34: =C33*(Assumptions!$C$15/Assumptions!$F$5) -> 140.25 | D34: =D33*(Assumptions!$C$15/Assumptions!$F$5) -> 172.656 | E34: =E33*(Assumptions!$C$15/Assumptions!$F$5) -> 213.32817 | F34: =F33*(Assumptions!$C$15/Assumptions!$F$5) -> 261.68478 | G34: =G33*(Assumptions!$C$15/Assumptions!$F$5) -> 317.04267 | H34: =H33*(Assumptions!$C$15/Assumptions!$F$5) -> 377.89851 | I34: =I33*(Assumptions!$C$15/Assumptions!$F$5) -> 442.69044 | J34: =J33*(Assumptions!$C$15/Assumptions!$F$5) -> 509.72705 | ... R34: =R33*(Assumptions!$C$15/Assumptions!$F$5) -> 960.95967
A35: → Replaced with CFL | C35: =C34*C14 -> 140.25 | D35: =D34*D14 -> 172.656 | E35: =E34*E14 -> 213.32817 | F35: =F34*F14 -> 261.68478 | G35: =G34*G14 -> 312.28703 | H35: =H34*H14 -> 366.56156 | I35: =I34*I14 -> 422.76937 | J35: =J34*J14 -> 479.14343 | ... R35: =R34*R14 -> 816.81572
A36: → Switched to LED | C36: =C34*C15 -> 0 | D36: =D34*D15 -> 0 | E36: =E34*E15 -> 0 | F36: =F34*F15 -> 0 | G36: =G34*G15 -> 4.75564 | H36: =H34*H15 -> 11.336955 | I36: =I34*I15 -> 19.92107 | J36: =J34*J15 -> 30.583623 | ... R36: =R34*R15 -> 144.14395
A37: Inflow from Std switching | C37: =C27 -> 216.48 | D37: =D27 -> 270.8376 | E37: =E27 -> 320.53432 | F37: =F27 -> 364.80742 | G37: =G27 -> 402.42106 | H37: =H27 -> 429.99152 | I37: =I27 -> 446.72479 | J37: =J27 -> 452.55632 | ... R37: =R27 -> 257.02667
A38: New build - CFL | C38: =Assumptions!$C$17*Assumptions!$C$19*C19 -> 19.2 | D38: =Assumptions!$C$17*Assumptions!$C$19*(1+Assumptions!$C$19)^(D$3-2010)*D19 -> 24.96 | E38: =Assumptions!$C$17*Assumptions!$C$19*(1+Assumptions!$C$19)^(E$3-2010)*E19 -> 31.15008 | F38: =Assumptions!$C$17*Assumptions!$C$19*(1+Assumptions!$C$19)^(F$3-2010)*F19 -> 37.79543 | G38: =Assumptions!$C$17*Assumptions!$C$19*(1+Assumptions!$C$19)^(G$3-2010)*G19 -> 44.922569 | H38: =Assumptions!$C$17*Assumptions!$C$19*(1+Assumptions!$C$19)^(H$3-2010)*H19 -> 52.559405 | I38: =Assumptions!$C$17*Assumptions!$C$19*(1+Assumptions!$C$19)^(I$3-2010)*I19 -> 60.735313 | J38: =Assumptions!$C$17*Assumptions!$C$19*(1+Assumptions!$C$19)^(J$3-2010)*J19 -> 69.481198 | K38: =Assumptions!$C$17*Assumptions!$C$19*(1+Assumptions!$C$19)^(K$3-2010)*K19 -> 78.829577 | ... R38: =Assumptions!$C$17*Assumptions!$C$19*(1+Assumptions!$C$19)^(R$3-2010)*R19 -> 164.24605
A39: Ending installed base | C39: =C33-C34+C35+C37+C38 -> 1255.68 | D39: =D33-D34+D35+D37+D38 -> 1551.4776 | E39: =E33-E34+E35+E37+E38 -> 1903.162 | F39: =F33-F34+F35+F37+F38 -> 2305.7648 | G39: =G33-G34+G35+G37+G38 -> 2748.3528 | H39: =H33-H34+H35+H37+H38 -> 3219.5668 | I39: =I33-I34+I35+I37+I38 -> 3707.1058 | J39: =J33-J34+J35+J37+J38 -> 4198.5597 | ... R39: =R33-R34+R35+R37+R38 -> 7265.9263
A41: LED
A42: Beginning installed base | C42: =Assumptions!C17*Assumptions!G6 -> 60 | D42: =C48 -> 76.524 | E42: =D48 -> 98.065776 | F42: =E48 -> 124.78735 | G42: =F48 -> 156.94396 | H42: =G48 -> 224.73991 | I42: =H48 -> 327.73682 | J42: =I48 -> 464.87395 | K42: =J48 -> 634.67728 | ... R42: =Q48 -> 2603.5948
A43: Burnouts | C43: =C42*(Assumptions!$C$15/Assumptions!$F$6) -> 1.32 | D43: =D42*(Assumptions!$C$15/Assumptions!$F$6) -> 1.683528 | E43: =E42*(Assumptions!$C$15/Assumptions!$F$6) -> 2.1574471 | F43: =F42*(Assumptions!$C$15/Assumptions!$F$6) -> 2.7453218 | G43: =G42*(Assumptions!$C$15/Assumptions!$F$6) -> 3.4527671 | H43: =H42*(Assumptions!$C$15/Assumptions!$F$6) -> 4.944278 | I43: =I42*(Assumptions!$C$15/Assumptions!$F$6) -> 7.2102099 | J43: =J42*(Assumptions!$C$15/Assumptions!$F$6) -> 10.227227 | ... R43: =R42*(Assumptions!$C$15/Assumptions!$F$6) -> 57.279086
A44: → Replaced with LED | C44: =C43 -> 1.32 | D44: =D43 -> 1.683528 | E44: =E43 -> 2.1574471 | F44: =F43 -> 2.7453218 | G44: =G43 -> 3.4527671 | H44: =H43 -> 4.944278 | I44: =I43 -> 7.2102099 | J44: =J43 -> 10.227227 | ... R44: =R43 -> 57.279086
A45: Inflow from Std switching | C45: =C28 -> 16.236 | D45: =D28 -> 16.250256 | E45: =E28 -> 16.026716 | F45: =F28 -> 15.634604 | G45: =G28 -> 40.242106 | H45: =H28 -> 62.109886 | I45: =I28 -> 80.410463 | J45: =J28 -> 94.625413 | ... R45: =R28 -> 85.224632
A46: Inflow from CFL switching | C46: =C36 -> 0 | D46: =D36 -> 0 | E46: =E36 -> 0 | F46: =F36 -> 0 | G46: =G36 -> 4.75564 | H46: =H36 -> 11.336955 | I46: =I36 -> 19.92107 | J46: =J36 -> 30.583623 | ... R46: =R36 -> 144.14395
A47: New build - LED | C47: =Assumptions!$C$17*Assumptions!$C$19*C20 -> 0.288 | D47: =Assumptions!$C$17*Assumptions!$C$19*(1+Assumptions!$C$19)^(D$3-2010)*D20 -> 5.29152 | E47: =Assumptions!$C$17*Assumptions!$C$19*(1+Assumptions!$C$19)^(E$3-2010)*E20 -> 10.694861 | F47: =Assumptions!$C$17*Assumptions!$C$19*(1+Assumptions!$C$19)^(F$3-2010)*F20 -> 16.522002 | G47: =Assumptions!$C$17*Assumptions!$C$19*(1+Assumptions!$C$19)^(G$3-2010)*G20 -> 22.798204 | H47: =Assumptions!$C$17*Assumptions!$C$19*(1+Assumptions!$C$19)^(H$3-2010)*H20 -> 29.550066 | I47: =Assumptions!$C$17*Assumptions!$C$19*(1+Assumptions!$C$19)^(I$3-2010)*I20 -> 36.8056 | J47: =Assumptions!$C$17*Assumptions!$C$19*(1+Assumptions!$C$19)^(J$3-2010)*J20 -> 44.594296 | K47: =Assumptions!$C$17*Assumptions!$C$19*(1+Assumptions!$C$19)^(K$3-2010)*K20 -> 52.947199 | ... R47: =Assumptions!$C$17*Assumptions!$C$19*(1+Assumptions!$C$19)^(R$3-2010)*R20 -> 130.1866
...

Sheet Supply & Utilization
A1: SUPPLY & UTILIZATION MODEL
A3: m bulbs | C3: 2010 | D3: 2011 | E3: 2012 | F3: 2013 | G3: 2014 | H3: 2015 | I3: 2016 | J3: 2017 | K3: 2018 | L3: 2019 | M3: 2020 | N3: 2021 | O3: 2022 | P3: 2023 | Q3: 2024 | R3: 2025
A5: INCANDESCENT CAPACITY
A6: GE | C6: =Assumptions!D54 -> 2300 | D6: =Assumptions!E54 -> 2250 | E6: =Assumptions!F54 -> 2150 | F6: =MAX(E6-100,0) -> 2050 | G6: =MAX(F6-100,0) -> 1950 | H6: =MAX(G6-100,0) -> 1850 | I6: =MAX(H6-100,0) -> 1750 | J6: =MAX(I6-100,0) -> 1650 | K6: =MAX(J6-100,0) -> 1550 | L6: =MAX(K6-100,0) -> 1450 | M6: =MAX(L6-100,0) -> 1350 | ... R6: =MAX(Q6-100,0) -> 850
A7: Philips | C7: =Assumptions!D55 -> 2200 | D7: =Assumptions!E55 -> 1800 | E7: =Assumptions!F55 -> 1500 | F7: =MAX(E7-200,0) -> 1300 | G7: =MAX(F7-200,0) -> 1100 | H7: =MAX(G7-200,0) -> 900 | I7: =MAX(H7-200,0) -> 700 | J7: =MAX(I7-200,0) -> 500 | K7: =MAX(J7-200,0) -> 300 | L7: =MAX(K7-200,0) -> 100 | M7: =MAX(L7-200,0) -> 0 | ... R7: =MAX(Q7-200,0) -> 0
A8: Osram | C8: =Assumptions!D56 -> 2700 | D8: =Assumptions!E56 -> 2600 | E8: =Assumptions!F56 -> 2300 | F8: =MAX(E8-150,0) -> 2150 | G8: =MAX(F8-150,0) -> 2000 | H8: =MAX(G8-150,0) -> 1850 | I8: =MAX(H8-150,0) -> 1700 | J8: =MAX(I8-150,0) -> 1550 | K8: =MAX(J8-150,0) -> 1400 | L8: =MAX(K8-150,0) -> 1250 | M8: =MAX(L8-150,0) -> 1100 | ... R8: =MAX(Q8-150,0) -> 350
A9: Other | C9: =Assumptions!D57 -> 2000 | D9: =Assumptions!E57 -> 1900 | E9: =Assumptions!F57 -> 1800 | F9: =MAX(E9-100,0) -> 1700 | G9: =MAX(F9-100,0) -> 1600 | H9: =MAX(G9-100,0) -> 1500 | I9: =MAX(H9-100,0) -> 1400 | J9: =MAX(I9-100,0) -> 1300 | K9: =MAX(J9-100,0) -> 1200 | L9: =MAX(K9-100,0) -> 1100 | M9: =MAX(L9-100,0) -> 1000 | ... R9: =MAX(Q9-100,0) -> 500
A10: Total Incandescent Capacity | C10: =SUM(C6:C9) -> 9200 | D10: =SUM(D6:D9) -> 8550 | E10: =SUM(E6:E9) -> 7750 | F10: =SUM(F6:F9) -> 7200 | G10: =SUM(G6:G9) -> 6650 | H10: =SUM(H6:H9) -> 6100 | I10: =SUM(I6:I9) -> 5550 | J10: =SUM(J6:J9) -> 5000 | ... R10: =SUM(R6:R9) -> 1700
A12: CFL CAPACITY
A13: GE | C13: =Assumptions!D60 -> 300 | D13: =Assumptions!E60 -> 500 | E13: =Assumptions!F60 -> 700 | F13: =E13+100 -> 800 | G13: =F13+100 -> 900 | H13: =G13+100 -> 1000 | I13: =H13+100 -> 1100 | J13: =I13+100 -> 1200 | K13: =J13+100 -> 1300 | L13: =K13+100 -> 1400 | M13: =L13+100 -> 1500 | ... R13: =Q13+100 -> 2000
A14: Philips | C14: =Assumptions!D61 -> 180 | D14: =Assumptions!E61 -> 220 | E14: =Assumptions!F61 -> 400 | F14: =E14+80 -> 480 | G14: =F14+80 -> 560 | H14: =G14+80 -> 640 | I14: =H14+80 -> 720 | J14: =I14+80 -> 800 | K14: =J14+80 -> 880 | L14: =K14+80 -> 960 | M14: =L14+80 -> 1040 | ... R14: =Q14+80 -> 1440
A15: Osram | C15: =Assumptions!D62 -> 360 | D15: =Assumptions!E62 -> 450 | E15: =Assumptions!F62 -> 650 | F15: =E15+100 -> 750 | G15: =F15+100 -> 850 | H15: =G15+100 -> 950 | I15: =H15+100 -> 1050 | J15: =I15+100 -> 1150 | K15: =J15+100 -> 1250 | L15: =K15+100 -> 1350 | M15: =L15+100 -> 1450 | ... R15: =Q15+100 -> 1950
A16: Other | C16: =Assumptions!D63 -> 120 | D16: =Assumptions!E63 -> 150 | E16: =Assumptions!F63 -> 200 | F16: =E16+50 -> 250 | G16: =F16+50 -> 300 | H16: =G16+50 -> 350 | I16: =H16+50 -> 400 | J16: =I16+50 -> 450 | K16: =J16+50 -> 500 | L16: =K16+50 -> 550 | M16: =L16+50 -> 600 | ... R16: =Q16+50 -> 850
A17: Total CFL Capacity | C17: =SUM(C13:C16) -> 960 | D17: =SUM(D13:D16) -> 1320 | E17: =SUM(E13:E16) -> 1950 | F17: =SUM(F13:F16) -> 2280 | G17: =SUM(G13:G16) -> 2610 | H17: =SUM(H13:H16) -> 2940 | I17: =SUM(I13:I16) -> 3270 | J17: =SUM(J13:J16) -> 3600 | ... R17: =SUM(R13:R16) -> 6240
A19: LED CAPACITY
A20: GE | C20: =Assumptions!D66 -> 10 | D20: =Assumptions!E66 -> 25 | E20: =Assumptions!F66 -> 60 | F20: =E20+40 -> 100 | G20: =F20+40 -> 140 | H20: =G20+40 -> 180 | I20: =H20+40 -> 220 | J20: =I20+40 -> 260 | K20: =J20+40 -> 300 | L20: =K20+40 -> 340 | M20: =L20+40 -> 380 | ... R20: =Q20+40 -> 580
A21: Philips | C21: =Assumptions!D67 -> 10 | D21: =Assumptions!E67 -> 45 | E21: =Assumptions!F67 -> 100 | F21: =E21+50 -> 150 | G21: =F21+50 -> 200 | H21: =G21+50 -> 250 | I21: =H21+50 -> 300 | J21: =I21+50 -> 350 | K21: =J21+50 -> 400 | L21: =K21+50 -> 450 | M21: =L21+50 -> 500 | ... R21: =Q21+50 -> 750
A22: Osram | C22: =Assumptions!D68 -> 15 | D22: =Assumptions!E68 -> 35 | E22: =Assumptions!F68 -> 80 | F22: =E22+45 -> 125 | G22: =F22+45 -> 170 | H22: =G22+45 -> 215 | I22: =H22+45 -> 260 | J22: =I22+45 -> 305 | K22: =J22+45 -> 350 | L22: =K22+45 -> 395 | M22: =L22+45 -> 440 | ... R22: =Q22+45 -> 665
A23: Other | C23: =Assumptions!D69 -> 20 | D23: =Assumptions!E69 -> 40 | E23: =Assumptions!F69 -> 60 | F23: =E23+30 -> 90 | G23: =F23+30 -> 120 | H23: =G23+30 -> 150 | I23: =H23+30 -> 180 | J23: =I23+30 -> 210 | K23: =J23+30 -> 240 | L23: =K23+30 -> 270 | M23: =L23+30 -> 300 | ... R23: =Q23+30 -> 450
A24: Total LED Capacity | C24: =SUM(C20:C23) -> 55 | D24: =SUM(D20:D23) -> 145 | E24: =SUM(E20:E23) -> 300 | F24: =SUM(F20:F23) -> 465 | G24: =SUM(G20:G23) -> 630 | H24: =SUM(H20:H23) -> 795 | I24: =SUM(I20:I23) -> 960 | J24: =SUM(J20:J23) -> 1125 | ... R24: =SUM(R20:R23) -> 2445
A26: GLOBAL DEMAND (m bulbs)
A27: Standard Demand | C27: ='Demand - Developed'!C53+'Demand - Emerging'!C53 -> 8980.95 | D27: ='Demand - Developed'!D53+'Demand - Emerging'!D53 -> 8367.8327 | E27: ='Demand - Developed'!E53+'Demand - Emerging'!E53 -> 7716.2992 | F27: ='Demand - Developed'!F53+'Demand - Emerging'!F53 -> 7053.3605 | G27: ='Demand - Developed'!G53+'Demand - Emerging'!G53 -> 6355.0075 | H27: ='Demand - Developed'!H53+'Demand - Emerging'!H53 -> 5651.4216 | I27: ='Demand - Developed'!I53+'Demand - Emerging'!I53 -> 4970.9408 | J27: ='Demand - Developed'!J53+'Demand - Emerging'!J53 -> 4332.8017 | ... R27: ='Demand - Developed'!R53+'Demand - Emerging'!R53 -> 1161.5154
A28: CFL Demand | C28: ='Demand - Developed'!C58+'Demand - Emerging'!C58 -> 978.5475 | D28: ='Demand - Developed'!D58+'Demand - Emerging'!D58 -> 1145.9817 | E28: ='Demand - Developed'!E58+'Demand - Emerging'!E58 -> 1296.2705 | F28: ='Demand - Developed'!F58+'Demand - Emerging'!F58 -> 1429.2983 | G28: ='Demand - Developed'!G58+'Demand - Emerging'!G58 -> 1529.9823 | H28: ='Demand - Developed'!H58+'Demand - Emerging'!H58 -> 1601.7042 | I28: ='Demand - Developed'!I58+'Demand - Emerging'!I58 -> 1648.1918 | J28: ='Demand - Developed'!J58+'Demand - Emerging'!J58 -> 1674.2763 | ... R28: ='Demand - Developed'!R58+'Demand - Emerging'!R58 -> 1680.2814
A29: LED Demand | C29: ='Demand - Developed'!C64+'Demand - Emerging'!C64 -> 60.774 | D29: ='Demand - Developed'!D64+'Demand - Emerging'!D64 -> 63.016914 | E29: ='Demand - Developed'!E64+'Demand - Emerging'!E64 -> 65.448273 | F29: ='Demand - Developed'!F64+'Demand - Emerging'!F64 -> 68.408205 | G29: ='Demand - Developed'!G64+'Demand - Emerging'!G64 -> 132.85604 | H29: ='Demand - Developed'!H64+'Demand - Emerging'!H64 -> 192.91146 | I29: ='Demand - Developed'!I64+'Demand - Emerging'!I64 -> 248.8323 | J29: ='Demand - Developed'!J64+'Demand - Emerging'!J64 -> 301.3721 | ... R29: ='Demand - Developed'!R64+'Demand - Emerging'!R64 -> 579.67671
A30: Total Global Demand | C30: =C27+C28+C29 -> 10020.272 | D30: =D27+D28+D29 -> 9576.8313 | E30: =E27+E28+E29 -> 9078.018 | F30: =F27+F28+F29 -> 8551.067 | G30: =G27+G28+G29 -> 8017.8459 | H30: =H27+H28+H29 -> 7446.0372 | I30: =I27+I28+I29 -> 6867.9649 | J30: =J27+J28+J29 -> 6308.4501 | ... R30: =R27+R28+R29 -> 3421.4736
A32: CAPACITY UTILIZATION (%)
A33: Incandescent Utilization | C33: =IF(C10>0,MIN(C27/C10,1),0) -> 0.97619022 | D33: =IF(D10>0,MIN(D27/D10,1),0) -> 0.97869388 | E33: =IF(E10>0,MIN(E27/E10,1),0) -> 0.99565151 | F33: =IF(F10>0,MIN(F27/F10,1),0) -> 0.9796334 | G33: =IF(G10>0,MIN(G27/G10,1),0) -> 0.95564023 | H33: =IF(H10>0,MIN(H27/H10,1),0) -> 0.92646255 | I33: =IF(I10>0,MIN(I27/I10,1),0) -> 0.89566502 | J33: =IF(J10>0,MIN(J27/J10,1),0) -> 0.86656033 | ... R33: =IF(R10>0,MIN(R27/R10,1),0) -> 0.68324438
A34: CFL Utilization | C34: =IF(C17>0,MIN(C28/C17,1),0) -> 1 | D34: =IF(D17>0,MIN(D28/D17,1),0) -> 0.86816799 | E34: =IF(E17>0,MIN(E28/E17,1),0) -> 0.66475413 | F34: =IF(F17>0,MIN(F28/F17,1),0) -> 0.62688521 | G34: =IF(G17>0,MIN(G28/G17,1),0) -> 0.58620012 | H34: =IF(H17>0,MIN(H28/H17,1),0) -> 0.54479735 | I34: =IF(I17>0,MIN(I28/I17,1),0) -> 0.50403418 | J34: =IF(J17>0,MIN(J28/J17,1),0) -> 0.46507676 | ... R34: =IF(R17>0,MIN(R28/R17,1),0) -> 0.26927587
A35: LED Utilization | C35: =IF(C24>0,MIN(C29/C24,1),0) -> 1 | D35: =IF(D24>0,MIN(D29/D24,1),0) -> 0.43459941 | E35: =IF(E24>0,MIN(E29/E24,1),0) -> 0.21816091 | F35: =IF(F24>0,MIN(F29/F24,1),0) -> 0.14711442 | G35: =IF(G24>0,MIN(G29/G24,1),0) -> 0.2108826 | H35: =IF(H24>0,MIN(H29/H24,1),0) -> 0.24265593 | I35: =IF(I24>0,MIN(I29/I24,1),0) -> 0.25920032 | J35: =IF(J24>0,MIN(J29/J24,1),0) -> 0.26788631 | ... R35: =IF(R24>0,MIN(R29/R24,1),0) -> 0.23708659
A36: Overall Industry Utilization | C36: =IF((C10+C17+C24)>0,MIN(C30/(C10+C17+C24),1),0) -> 0.980937 | D36: =IF((D10+D17+D24)>0,MIN(D30/(D10+D17+D24),1),0) -> 0.95624876 | E36: =IF((E10+E17+E24)>0,MIN(E30/(E10+E17+E24),1),0) -> 0.9078018 | F36: =IF((F10+F17+F24)>0,MIN(F30/(F10+F17+F24),1),0) -> 0.85983579 | G36: =IF((G10+G17+G24)>0,MIN(G30/(G10+G17+G24),1),0) -> 0.81070231 | H36: =IF((H10+H17+H24)>0,MIN(H30/(H10+H17+H24),1),0) -> 0.7570958 | I36: =IF((I10+I17+I24)>0,MIN(I30/(I10+I17+I24),1),0) -> 0.7022459 | J36: =IF((J10+J17+J24)>0,MIN(J30/(J10+J17+J24),1),0) -> 0.64868382 | ... R36: =IF((R10+R17+R24)>0,MIN(R30/(R10+R17+R24),1),0) -> 0.32946303
A38: GE CAPACITY SHARE (%)
A39: GE Incandescent Share | C39: =IF(C10>0,C6/C10,0) -> 0.25 | D39: =IF(D10>0,D6/D10,0) -> 0.26315789 | E39: =IF(E10>0,E6/E10,0) -> 0.27741935 | F39: =IF(F10>0,F6/F10,0) -> 0.28472222 | G39: =IF(G10>0,G6/G10,0) -> 0.29323308 | H39: =IF(H10>0,H6/H10,0) -> 0.30327869 | I39: =IF(I10>0,I6/I10,0) -> 0.31531532 | J39: =IF(J10>0,J6/J10,0) -> 0.33 | ... R39: =IF(R10>0,R6/R10,0) -> 0.5
A40: GE CFL Share | C40: =IF(C17>0,C13/C17,0) -> 0.3125 | D40: =IF(D17>0,D13/D17,0) -> 0.37878788 | E40: =IF(E17>0,E13/E17,0) -> 0.35897436 | F40: =IF(F17>0,F13/F17,0) -> 0.35087719 | G40: =IF(G17>0,G13/G17,0) -> 0.34482759 | H40: =IF(H17>0,H13/H17,0) -> 0.34013605 | I40: =IF(I17>0,I13/I17,0) -> 0.33639144 | J40: =IF(J17>0,J13/J17,0) -> 0.33333333 | ... R40: =IF(R17>0,R13/R17,0) -> 0.32051282
A41: GE LED Share | C41: =IF(C24>0,C20/C24,0) -> 0.18181818 | D41: =IF(D24>0,D20/D24,0) -> 0.17241379 | E41: =IF(E24>0,E20/E24,0) -> 0.2 | F41: =IF(F24>0,F20/F24,0) -> 0.21505376 | G41: =IF(G24>0,G20/G24,0) -> 0.22222222 | H41: =IF(H24>0,H20/H24,0) -> 0.22641509 | I41: =IF(I24>0,I20/I24,0) -> 0.22916667 | J41: =IF(J24>0,J20/J24,0) -> 0.23111111 | ... R41: =IF(R24>0,R20/R24,0) -> 0.23721881
A43: GE DEMAND (m bulbs)
A44: GE Standard Demand | C44: =MIN(C27*C39,C6) -> 2245.2375 | D44: =MIN(D27*D39,D6) -> 2202.0612 | E44: =MIN(E27*E39,E6) -> 2140.6507 | F44: =MIN(F27*F39,F6) -> 2008.2485 | G44: =MIN(G27*G39,G6) -> 1863.4984 | H44: =MIN(H27*H39,H6) -> 1713.9557 | I44: =MIN(I27*I39,I6) -> 1567.4138 | J44: =MIN(J27*J39,J6) -> 1429.8246 | ... R44: =MIN(R27*R39,R6) -> 580.75772
A45: GE CFL Demand | C45: =MIN(C28*C40,C13) -> 300 | D45: =MIN(D28*D40,D13) -> 434.08399 | E45: =MIN(E28*E40,E13) -> 465.32789 | F45: =MIN(F28*F40,F13) -> 501.50817 | G45: =MIN(G28*G40,G13) -> 527.58011 | H45: =MIN(H28*H40,H13) -> 544.79735 | I45: =MIN(I28*I40,I13) -> 554.4376 | J45: =MIN(J28*J40,J13) -> 558.09211 | ... R45: =MIN(R28*R40,R13) -> 538.55175
A46: GE LED Demand | C46: =MIN(C29*C41,C20) -> 10 | D46: =MIN(D29*D41,D20) -> 10.864985 | E46: =MIN(E29*E41,E20) -> 13.089655 | F46: =MIN(F29*F41,F20) -> 14.711442 | G46: =MIN(G29*G41,G20) -> 29.523563 | H46: =MIN(H29*H41,H20) -> 43.678067 | I46: =MIN(I29*I41,I20) -> 57.02407 | J46: =MIN(J29*J41,J20) -> 69.650441 | ... R46: =MIN(R29*R41,R20) -> 137.51022
A47: GE Total Demand | C47: =C44+C45+C46 -> 2555.2375 | D47: =D44+D45+D46 -> 2647.0102 | E47: =E44+E45+E46 -> 2619.0683 | F47: =F44+F45+F46 -> 2524.4681 | G47: =G44+G45+G46 -> 2420.6021 | H47: =H44+H45+H46 -> 2302.4311 | I47: =I44+I45+I46 -> 2178.8754 | J47: =J44+J45+J46 -> 2057.5671 | ... R47: =R44+R45+R46 -> 1256.8197

Sheet GE FINANCIALS — DEVELOPED MARKE
A1: GE FINANCIALS — DEVELOPED MARKETS
A2: $million
C3: 2010 | D3: 2011 | E3: 2012 | F3: 2013 | G3: 2014 | H3: 2015 | I3: 2016 | J3: 2017 | K3: 2018 | L3: 2019 | M3: 2020 | N3: 2021 | O3: 2022 | P3: 2023 | Q3: 2024 | R3: 2025
A5: GE VOLUME - DEVELOPED (m bulbs)
A6: Developed % of global demand | C6: ='Demand - Developed'!C66/'Supply & Utilization'!C30 -> 0.42016601 | D6: ='Demand - Developed'!D66/'Supply & Utilization'!D30 -> 0.39012275 | E6: ='Demand - Developed'!E66/'Supply & Utilization'!E30 -> 0.3591874 | F6: ='Demand - Developed'!F66/'Supply & Utilization'!F30 -> 0.32804503 | G6: ='Demand - Developed'!G66/'Supply & Utilization'!G30 -> 0.29762622 | H6: ='Demand - Developed'!H66/'Supply & Utilization'!H30 -> 0.26772821 | I6: ='Demand - Developed'!I66/'Supply & Utilization'!I30 -> 0.23982938 | J6: ='Demand - Developed'!J66/'Supply & Utilization'!J30 -> 0.21534986 | ... R6: ='Demand - Developed'!R66/'Supply & Utilization'!R30 -> 0.18069304
A7: GE Standard Volume | C7: ='Supply & Utilization'!C44*C6 -> 943.37248 | D7: ='Supply & Utilization'!D44*D6 -> 859.07419 | E7: ='Supply & Utilization'!E44*E6 -> 768.89478 | F7: ='Supply & Utilization'!F44*F6 -> 658.79593 | G7: ='Supply & Utilization'!G44*G6 -> 554.626 | H7: ='Supply & Utilization'!H44*H6 -> 458.8743 | I7: ='Supply & Utilization'!I44*I6 -> 375.91187 | J7: ='Supply & Utilization'!J44*J6 -> 307.91251 | ... R7: ='Supply & Utilization'!R44*R6 -> 104.93888
A8: GE CFL Volume | C8: ='Supply & Utilization'!C45*C6 -> 126.0498 | D8: ='Supply & Utilization'!D45*D6 -> 169.34604 | E8: ='Supply & Utilization'!E45*E6 -> 167.13991 | F8: ='Supply & Utilization'!F45*F6 -> 164.51726 | G8: ='Supply & Utilization'!G45*G6 -> 157.02167 | H8: ='Supply & Utilization'!H45*H6 -> 145.85762 | I8: ='Supply & Utilization'!I45*I6 -> 132.97043 | J8: ='Supply & Utilization'!J45*J6 -> 120.18506 | ... R8: ='Supply & Utilization'!R45*R6 -> 97.312553
A9: GE LED Volume | C9: ='Supply & Utilization'!C46*C6 -> 4.2016601 | D9: ='Supply & Utilization'!D46*D6 -> 4.2386779 | E9: ='Supply & Utilization'!E46*E6 -> 4.701639 | F9: ='Supply & Utilization'!F46*F6 -> 4.8260154 | G9: ='Supply & Utilization'!G46*G6 -> 8.7869867 | H9: ='Supply & Utilization'!H46*H6 -> 11.693851 | I9: ='Supply & Utilization'!I46*I6 -> 13.676047 | J9: ='Supply & Utilization'!J46*J6 -> 14.999212 | ... R9: ='Supply & Utilization'!R46*R6 -> 24.84714
A10: GE Total Volume - Developed | C10: =C7+C8+C9 -> 1073.6239 | D10: =D7+D8+D9 -> 1032.6589 | E10: =E7+E8+E9 -> 940.73633 | F10: =F7+F8+F9 -> 828.13921 | G10: =G7+G8+G9 -> 720.43466 | H10: =H7+H8+H9 -> 616.42576 | I10: =I7+I8+I9 -> 522.55835 | J10: =J7+J8+J9 -> 443.09678 | ... R10: =R7+R8+R9 -> 227.09857
A12: REVENUE ($m)
A13: Standard Revenue | C13: =C7*'Demand - Developed'!C6 -> 471.68624 | D13: =D7*'Demand - Developed'!D6 -> 429.53709 | E13: =E7*'Demand - Developed'!E6 -> 384.44739 | F13: =F7*'Demand - Developed'!F6 -> 329.39796 | G13: =G7*'Demand - Developed'!G6 -> 277.313 | H13: =H7*'Demand - Developed'!H6 -> 229.43715 | I13: =I7*'Demand - Developed'!I6 -> 187.95594 | J13: =J7*'Demand - Developed'!J6 -> 153.95626 | ... R13: =R7*'Demand - Developed'!R6 -> 52.469439
A14: CFL Revenue | C14: =C8*'Demand - Developed'!C7 -> 378.14941 | D14: =D8*'Demand - Developed'!D7 -> 487.7166 | E14: =E8*'Demand - Developed'!E7 -> 462.10844 | F14: =F8*'Demand - Developed'!F7 -> 436.66303 | G14: =G8*'Demand - Developed'!G7 -> 400.09746 | H14: =H8*'Demand - Developed'!H7 -> 356.78496 | I14: =I8*'Demand - Developed'!I7 -> 312.25091 | J14: =J8*'Demand - Developed'!J7 -> 270.93827 | ... R14: =R8*'Demand - Developed'!R7 -> 158.25543
A15: LED Revenue | C15: =C9*'Demand - Developed'!C8 -> 168.0664 | D15: =D9*'Demand - Developed'!D8 -> 152.59241 | E15: =E9*'Demand - Developed'!E8 -> 152.3331 | F15: =F9*'Demand - Developed'!F8 -> 140.72661 | G15: =G9*'Demand - Developed'!G8 -> 230.60568 | H15: =H9*'Demand - Developed'!H8 -> 276.20408 | I15: =I9*'Demand - Developed'!I8 -> 290.72049 | J15: =J9*'Demand - Developed'!J8 -> 286.96307 | ... R15: =R9*'Demand - Developed'!R8 -> 204.63223
A16: Total Revenue | C16: =C13+C14+C15 -> 1017.9021 | D16: =D13+D14+D15 -> 1069.8461 | E16: =E13+E14+E15 -> 998.88893 | F16: =F13+F14+F15 -> 906.78761 | G16: =G13+G14+G15 -> 908.01614 | H16: =H13+H14+H15 -> 862.42618 | I16: =I13+I14+I15 -> 790.92733 | J16: =J13+J14+J15 -> 711.8576 | ... R16: =R13+R14+R15 -> 415.3571
A18: GROSS MARGIN
A19: Std Gross Margin % | C19: =MAX(Assumptions!$C$82+(('Supply & Utilization'!C33-Assumptions!$C$87)*Assumptions!$C$86/0.01),0.02) -> 0.19309511 | D19: =MAX(Assumptions!$C$82+(('Supply & Utilization'!D33-Assumptions!$C$87)*Assumptions!$C$86/0.01),0.02) -> 0.19434694 | E19: =MAX(Assumptions!$C$82+(('Supply & Utilization'!E33-Assumptions!$C$87)*Assumptions!$C$86/0.01),0.02) -> 0.20282575 | F19: =MAX(Assumptions!$C$82+(('Supply & Utilization'!F33-Assumptions!$C$87)*Assumptions!$C$86/0.01),0.02) -> 0.1948167 | G19: =MAX(Assumptions!$C$82+(('Supply & Utilization'!G33-Assumptions!$C$87)*Assumptions!$C$86/0.01),0.02) -> 0.18282012 | H19: =MAX(Assumptions!$C$82+(('Supply & Utilization'!H33-Assumptions!$C$87)*Assumptions!$C$86/0.01),0.02) -> 0.16823128 | I19: =MAX(Assumptions!$C$82+(('Supply & Utilization'!I33-Assumptions!$C$87)*Assumptions!$C$86/0.01),0.02) -> 0.15283251 | J19: =MAX(Assumptions!$C$82+(('Supply & Utilization'!J33-Assumptions!$C$87)*Assumptions!$C$86/0.01),0.02) -> 0.13828017 | ... R19: =MAX(Assumptions!$C$82+(('Supply & Utilization'!R33-Assumptions!$C$87)*Assumptions!$C$86/0.01),0.02) -> 0.046622188
A20: CFL Gross Margin % | C20: =MAX(Assumptions!$C$83+(('Supply & Utilization'!C34-Assumptions!$C$87)*Assumptions!$C$86/0.01),0.02) -> 0.255 | D20: =MAX(Assumptions!$C$83+(('Supply & Utilization'!D34-Assumptions!$C$87)*Assumptions!$C$86/0.01),0.02) -> 0.18908399 | E20: =MAX(Assumptions!$C$83+(('Supply & Utilization'!E34-Assumptions!$C$87)*Assumptions!$C$86/0.01),0.02) -> 0.087377063 | F20: =MAX(Assumptions!$C$83+(('Supply & Utilization'!F34-Assumptions!$C$87)*Assumptions!$C$86/0.01),0.02) -> 0.068442607 | G20: =MAX(Assumptions!$C$83+(('Supply & Utilization'!G34-Assumptions!$C$87)*Assumptions!$C$86/0.01),0.02) -> 0.048100059 | H20: =MAX(Assumptions!$C$83+(('Supply & Utilization'!H34-Assumptions!$C$87)*Assumptions!$C$86/0.01),0.02) -> 0.027398673 | I20: =MAX(Assumptions!$C$83+(('Supply & Utilization'!I34-Assumptions!$C$87)*Assumptions!$C$86/0.01),0.02) -> 0.02 | J20: =MAX(Assumptions!$C$83+(('Supply & Utilization'!J34-Assumptions!$C$87)*Assumptions!$C$86/0.01),0.02) -> 0.02 | ... R20: =MAX(Assumptions!$C$83+(('Supply & Utilization'!R34-Assumptions!$C$87)*Assumptions!$C$86/0.01),0.02) -> 0.02
A21: LED Gross Margin % | C21: =MAX(Assumptions!$C$84+(('Supply & Utilization'!C35-Assumptions!$C$87)*Assumptions!$C$86/0.01),0.02) -> 0.275 | D21: =MAX(Assumptions!$C$84+(('Supply & Utilization'!D35-Assumptions!$C$87)*Assumptions!$C$86/0.01),0.02) -> 0.02 | E21: =MAX(Assumptions!$C$84+(('Supply & Utilization'!E35-Assumptions!$C$87)*Assumptions!$C$86/0.01),0.02) -> 0.02 | F21: =MAX(Assumptions!$C$84+(('Supply & Utilization'!F35-Assumptions!$C$87)*Assumptions!$C$86/0.01),0.02) -> 0.02 | G21: =MAX(Assumptions!$C$84+(('Supply & Utilization'!G35-Assumptions!$C$87)*Assumptions!$C$86/0.01),0.02) -> 0.02 | H21: =MAX(Assumptions!$C$84+(('Supply & Utilization'!H35-Assumptions!$C$87)*Assumptions!$C$86/0.01),0.02) -> 0.02 | I21: =MAX(Assumptions!$C$84+(('Supply & Utilization'!I35-Assumptions!$C$87)*Assumptions!$C$86/0.01),0.02) -> 0.02 | J21: =MAX(Assumptions!$C$84+(('Supply & Utilization'!J35-Assumptions!$C$87)*Assumptions!$C$86/0.01),0.02) -> 0.02 | ... R21: =MAX(Assumptions!$C$84+(('Supply & Utilization'!R35-Assumptions!$C$87)*Assumptions!$C$86/0.01),0.02) -> 0.02
A22: Std Gross Margin $m | C22: =C13*C19 -> 91.080306 | D22: =D13*D19 -> 83.47922 | E22: =E13*E19 -> 77.975831 | F22: =F13*F19 -> 64.172224 | G22: =G13*G19 -> 50.698395 | H22: =H13*H19 -> 38.598504 | I22: =I13*I19 -> 28.725777 | J22: =J13*J19 -> 21.289097 | ... R22: =R13*R19 -> 2.4462401
A23: CFL Gross Margin $m | C23: =C14*C20 -> 96.428099 | D23: =D14*D20 -> 92.219404 | E23: =E14*E20 -> 40.377678 | F23: =F14*F20 -> 29.886356 | G23: =G14*G20 -> 19.244711 | H23: =H14*H20 -> 9.7754343 | I23: =I14*I20 -> 6.2450182 | J23: =J14*J20 -> 5.4187655 | ... R23: =R14*R20 -> 3.1651086
A24: LED Gross Margin $m | C24: =C15*C21 -> 46.218261 | D24: =D15*D21 -> 3.0518481 | E24: =E15*E21 -> 3.0466621 | F24: =F15*F21 -> 2.8145322 | G24: =G15*G21 -> 4.6121136 | H24: =H15*H21 -> 5.5240815 | I24: =I15*I21 -> 5.8144098 | J24: =J15*J21 -> 5.7392614 | ... R24: =R15*R21 -> 4.0926447
A25: Total Gross Margin | C25: =C22+C23+C24 -> 233.72667 | D25: =D22+D23+D24 -> 178.75047 | E25: =E22+E23+E24 -> 121.40017 | F25: =F22+F23+F24 -> 96.873113 | G25: =G22+G23+G24 -> 74.55522 | H25: =H22+H23+H24 -> 53.89802 | I25: =I22+I23+I24 -> 40.785205 | J25: =J22+J23+J24 -> 32.447124 | ... R25: =R22+R23+R24 -> 9.7039933
A27: COSTS & FREE CASH FLOW
A28: Fixed Plant Costs - Std | C28: =-'Supply & Utilization'!C6*Assumptions!$D$74/1000*C6 -> -16.718406 | D28: =-'Supply & Utilization'!D6*Assumptions!$D$74/1000*D6 -> -15.185528 | E28: =-'Supply & Utilization'!E6*Assumptions!$D$74/1000*E6 -> -13.359975 | F28: =-'Supply & Utilization'!F6*Assumptions!$D$74/1000*F6 -> -11.634117 | G28: =-'Supply & Utilization'!G6*Assumptions!$D$74/1000*G6 -> -10.040421 | H28: =-'Supply & Utilization'!H6*Assumptions!$D$74/1000*H6 -> -8.5686413 | I28: =-'Supply & Utilization'!I6*Assumptions!$D$74/1000*I6 -> -7.2608345 | J28: =-'Supply & Utilization'!J6*Assumptions!$D$74/1000*J6 -> -6.1471616 | ... R28: =-'Supply & Utilization'!R6*Assumptions!$D$74/1000*R6 -> -2.6570912
A29: Fixed Plant Costs - CFL | C29: =-'Supply & Utilization'!C13*Assumptions!$D$75/1000*C6 -> -11.344482 | D29: =-'Supply & Utilization'!D13*Assumptions!$D$75/1000*D6 -> -17.555524 | E29: =-'Supply & Utilization'!E13*Assumptions!$D$75/1000*E6 -> -22.628806 | F29: =-'Supply & Utilization'!F13*Assumptions!$D$75/1000*F6 -> -23.619242 | G29: =-'Supply & Utilization'!G13*Assumptions!$D$75/1000*G6 -> -24.107724 | H29: =-'Supply & Utilization'!H13*Assumptions!$D$75/1000*H6 -> -24.095539 | I29: =-'Supply & Utilization'!I13*Assumptions!$D$75/1000*I6 -> -23.743109 | J29: =-'Supply & Utilization'!J13*Assumptions!$D$75/1000*J6 -> -23.257784 | ... R29: =-'Supply & Utilization'!R13*Assumptions!$D$75/1000*R6 -> -32.524747
A30: Fixed Plant Costs - LED | C30: =-'Supply & Utilization'!C20*Assumptions!$D$76/1000*C6 -> -6.3024902 | D30: =-'Supply & Utilization'!D20*Assumptions!$D$76/1000*D6 -> -14.629603 | E30: =-'Supply & Utilization'!E20*Assumptions!$D$76/1000*E6 -> -32.326866 | F30: =-'Supply & Utilization'!F20*Assumptions!$D$76/1000*F6 -> -49.206754 | G30: =-'Supply & Utilization'!G20*Assumptions!$D$76/1000*G6 -> -62.501507 | H30: =-'Supply & Utilization'!H20*Assumptions!$D$76/1000*H6 -> -72.286616 | I30: =-'Supply & Utilization'!I20*Assumptions!$D$76/1000*I6 -> -79.143695 | J30: =-'Supply & Utilization'!J20*Assumptions!$D$76/1000*J6 -> -83.986444 | ... R30: =-'Supply & Utilization'!R20*Assumptions!$D$76/1000*R6 -> -157.20295
A31: Total Fixed Costs | C31: =C28+C29+C30 -> -34.365378 | D31: =D28+D29+D30 -> -47.370655 | E31: =E28+E29+E30 -> -68.315648 | F31: =F28+F29+F30 -> -84.460113 | G31: =G28+G29+G30 -> -96.649651 | H31: =H28+H29+H30 -> -104.9508 | I31: =I28+I29+I30 -> -110.14764 | J31: =J28+J29+J30 -> -113.39139 | ... R31: =R28+R29+R30 -> -192.38478
A33: EBITDA | C33: =C25+C31 -> 199.36129 | D33: =D25+D31 -> 131.37982 | E33: =E25+E31 -> 53.084524 | F33: =F25+F31 -> 12.413 | G33: =G25+G31 -> -22.094431 | H33: =H25+H31 -> -51.052776 | I33: =I25+I31 -> -69.362433 | J33: =J25+J31 -> -80.944266 | ... R33: =R25+R31 -> -182.68079
A35: CAPEX - CFL (new capacity) | C35: =-MAX('Supply & Utilization'!C13-'Supply & Utilization'!C13,0)*Assumptions!$C$75/1000*C6 -> 0 | D35: =-MAX('Supply & Utilization'!D13-'Supply & Utilization'!C13,0)*Assumptions!$C$75/1000*D6 -> -46.81473 | E35: =-MAX('Supply & Utilization'!E13-'Supply & Utilization'!D13,0)*Assumptions!$C$75/1000*E6 -> -43.102488 | F35: =-MAX('Supply & Utilization'!F13-'Supply & Utilization'!E13,0)*Assumptions!$C$75/1000*F6 -> -19.682702 | G35: =-MAX('Supply & Utilization'!G13-'Supply & Utilization'!F13,0)*Assumptions!$C$75/1000*G6 -> -17.857573 | H35: =-MAX('Supply & Utilization'!H13-'Supply & Utilization'!G13,0)*Assumptions!$C$75/1000*H6 -> -16.063693 | I35: =-MAX('Supply & Utilization'!I13-'Supply & Utilization'!H13,0)*Assumptions!$C$75/1000*I6 -> -14.389763 | J35: =-MAX('Supply & Utilization'!J13-'Supply & Utilization'!I13,0)*Assumptions!$C$75/1000*J6 -> -12.920991 | K35: =-MAX('Supply & Utilization'!K13-'Supply & Utilization'!J13,0)*Assumptions!$C$75/1000*K6 -> -11.72479 | ... R35: =-MAX('Supply & Utilization'!R13-'Supply & Utilization'!Q13,0)*Assumptions!$C$75/1000*R6 -> -10.841582
A36: CAPEX - LED (new capacity) | C36: =-MAX('Supply & Utilization'!C20-'Supply & Utilization'!C20,0)*Assumptions!$C$76/1000*C6 -> 0 | D36: =-MAX('Supply & Utilization'!D20-'Supply & Utilization'!C20,0)*Assumptions!$C$76/1000*D6 -> -23.407365 | E36: =-MAX('Supply & Utilization'!E20-'Supply & Utilization'!D20,0)*Assumptions!$C$76/1000*E6 -> -50.286236 | F36: =-MAX('Supply & Utilization'!F20-'Supply & Utilization'!E20,0)*Assumptions!$C$76/1000*F6 -> -52.487205 | G36: =-MAX('Supply & Utilization'!G20-'Supply & Utilization'!F20,0)*Assumptions!$C$76/1000*G6 -> -47.620196 | H36: =-MAX('Supply & Utilization'!H20-'Supply & Utilization'!G20,0)*Assumptions!$C$76/1000*H6 -> -42.836513 | I36: =-MAX('Supply & Utilization'!I20-'Supply & Utilization'!H20,0)*Assumptions!$C$76/1000*I6 -> -38.372701 | J36: =-MAX('Supply & Utilization'!J20-'Supply & Utilization'!I20,0)*Assumptions!$C$76/1000*J6 -> -34.455977 | K36: =-MAX('Supply & Utilization'!K20-'Supply & Utilization'!J20,0)*Assumptions!$C$76/1000*K6 -> -31.266106 | ... R36: =-MAX('Supply & Utilization'!R20-'Supply & Utilization'!Q20,0)*Assumptions!$C$76/1000*R6 -> -28.910887
A37: Total CAPEX | C37: =C35+C36 -> 0 | D37: =D35+D36 -> -70.222096 | E37: =E35+E36 -> -93.388724 | F37: =F35+F36 -> -72.169906 | G37: =G35+G36 -> -65.477769 | H37: =H35+H36 -> -58.900206 | I37: =I35+I36 -> -52.762463 | J37: =J35+J36 -> -47.376968 | ... R37: =R35+R36 -> -39.752469
A39: Cash Taxes (25%) | C39: =-MAX(C33,0)*Assumptions!$C$24 -> -49.840322 | D39: =-MAX(D33,0)*Assumptions!$C$24 -> -32.844954 | E39: =-MAX(E33,0)*Assumptions!$C$24 -> -13.271131 | F39: =-MAX(F33,0)*Assumptions!$C$24 -> -3.1032499 | G39: =-MAX(G33,0)*Assumptions!$C$24 -> 0 | H39: =-MAX(H33,0)*Assumptions!$C$24 -> 0 | I39: =-MAX(I33,0)*Assumptions!$C$24 -> 0 | J39: =-MAX(J33,0)*Assumptions!$C$24 -> 0 | ... R39: =-MAX(R33,0)*Assumptions!$C$24 -> 0
A40: Change in Working Capital | C40: =-C16*Assumptions!$C$26 -> -50.895103 | D40: =-(D16-C16)*Assumptions!$C$26 -> -2.5972024 | E40: =-(E16-D16)*Assumptions!$C$26 -> 3.5478587 | F40: =-(F16-E16)*Assumptions!$C$26 -> 4.6050662 | G40: =-(G16-F16)*Assumptions!$C$26 -> -0.061426456 | H40: =-(H16-G16)*Assumptions!$C$26 -> 2.2794977 | I40: =-(I16-H16)*Assumptions!$C$26 -> 3.5749424 | J40: =-(J16-I16)*Assumptions!$C$26 -> 3.9534867 | K40: =-(K16-J16)*Assumptions!$C$26 -> 3.6791296 | ... R40: =-(R16-Q16)*Assumptions!$C$26 -> 0.70385129
A41: Corporate Overhead (allocated) | C41: =-Assumptions!$C$27*C6 -> -2.5209961 | D41: =-Assumptions!$C$27*D6 -> -2.3407365 | E41: =-Assumptions!$C$27*E6 -> -2.1551244 | F41: =-Assumptions!$C$27*F6 -> -1.9682702 | G41: =-Assumptions!$C$27*G6 -> -1.7857573 | H41: =-Assumptions!$C$27*H6 -> -1.6063693 | I41: =-Assumptions!$C$27*I6 -> -1.4389763 | J41: =-Assumptions!$C$27*J6 -> -1.2920991 | ... R41: =-Assumptions!$C$27*R6 -> -1.0841582
A43: FREE CASH FLOW - DEVELOPED | C43: =C33+C37+C39+C40+C41 -> 96.104868 | D43: =D33+D37+D39+D40+D41 -> 23.374828 | E43: =E33+E37+E39+E40+E41 -> -52.182597 | F43: =F33+F37+F39+F40+F41 -> -60.223361 | G43: =G33+G37+G39+G40+G41 -> -89.419384 | H43: =H33+H37+H39+H40+H41 -> -109.27985 | I43: =I33+I37+I39+I40+I41 -> -119.98893 | J43: =J33+J37+J39+J40+J41 -> -125.65985 | ... R43: =R33+R37+R39+R40+R41 -> -222.81357

Sheet GE Financials - Emerging
A1: GE FINANCIALS — EMERGING MARKETS
A2: $million
C3: 2010 | D3: 2011 | E3: 2012 | F3: 2013 | G3: 2014 | H3: 2015 | I3: 2016 | J3: 2017 | K3: 2018 | L3: 2019 | M3: 2020 | N3: 2021 | O3: 2022 | P3: 2023 | Q3: 2024 | R3: 2025
A5: GE VOLUME - EMERGING (m bulbs)
A6: Emerging % of global demand | C6: =1-'GE FINANCIALS — DEVELOPED MARKE'!C6 -> 0.57983399 | D6: =1-'GE FINANCIALS — DEVELOPED MARKE'!D6 -> 0.60987725 | E6: =1-'GE FINANCIALS — DEVELOPED MARKE'!E6 -> 0.6408126 | F6: =1-'GE FINANCIALS — DEVELOPED MARKE'!F6 -> 0.67195497 | G6: =1-'GE FINANCIALS — DEVELOPED MARKE'!G6 -> 0.70237378 | H6: =1-'GE FINANCIALS — DEVELOPED MARKE'!H6 -> 0.73227179 | I6: =1-'GE FINANCIALS — DEVELOPED MARKE'!I6 -> 0.76017062 | J6: =1-'GE FINANCIALS — DEVELOPED MARKE'!J6 -> 0.78465014 | ... R6: =1-'GE FINANCIALS — DEVELOPED MARKE'!R6 -> 0.81930696
A7: GE Standard Volume | C7: ='Supply & Utilization'!C44*C6 -> 1301.865 | D7: ='Supply & Utilization'!D44*D6 -> 1342.987 | E7: ='Supply & Utilization'!E44*E6 -> 1371.756 | F7: ='Supply & Utilization'!F44*F6 -> 1349.4525 | G7: ='Supply & Utilization'!G44*G6 -> 1308.8724 | H7: ='Supply & Utilization'!H44*H6 -> 1255.0814 | I7: ='Supply & Utilization'!I44*I6 -> 1191.5019 | J7: ='Supply & Utilization'!J44*J6 -> 1121.912 | ... R7: ='Supply & Utilization'!R44*R6 -> 475.81884
A8: GE CFL Volume | C8: ='Supply & Utilization'!C45*C6 -> 173.9502 | D8: ='Supply & Utilization'!D45*D6 -> 264.73795 | E8: ='Supply & Utilization'!E45*E6 -> 298.18797 | F8: ='Supply & Utilization'!F45*F6 -> 336.99091 | G8: ='Supply & Utilization'!G45*G6 -> 370.55843 | H8: ='Supply & Utilization'!H45*H6 -> 398.93973 | I8: ='Supply & Utilization'!I45*I6 -> 421.46717 | J8: ='Supply & Utilization'!J45*J6 -> 437.90706 | ... R8: ='Supply & Utilization'!R45*R6 -> 441.23919
A9: GE LED Volume | C9: ='Supply & Utilization'!C46*C6 -> 5.7983399 | D9: ='Supply & Utilization'!D46*D6 -> 6.6263072 | E9: ='Supply & Utilization'!E46*E6 -> 8.3880156 | F9: ='Supply & Utilization'!F46*F6 -> 9.8854266 | G9: ='Supply & Utilization'!G46*G6 -> 20.736577 | H9: ='Supply & Utilization'!H46*H6 -> 31.984217 | I9: ='Supply & Utilization'!I46*I6 -> 43.348022 | J9: ='Supply & Utilization'!J46*J6 -> 54.651228 | ... R9: ='Supply & Utilization'!R46*R6 -> 112.66308
A10: GE Total Volume - Emerging | C10: =C7+C8+C9 -> 1481.6136 | D10: =D7+D8+D9 -> 1614.3513 | E10: =E7+E8+E9 -> 1678.332 | F10: =F7+F8+F9 -> 1696.3289 | G10: =G7+G8+G9 -> 1700.1675 | H10: =H7+H8+H9 -> 1686.0054 | I10: =I7+I8+I9 -> 1656.3171 | J10: =J7+J8+J9 -> 1614.4703 | ... R10: =R7+R8+R9 -> 1029.7211
A12: REVENUE ($m)
